[2023-11-18T04:38:50.273+0000] {taskinstance.py:1159} INFO - Dependencies all met for dep_context=non-requeueable deps ti=<TaskInstance: etl_procesing.train_model manual__2023-11-18T04:33:23.188592+00:00 [queued]>
[2023-11-18T04:38:50.287+0000] {taskinstance.py:1159} INFO - Dependencies all met for dep_context=requeueable deps ti=<TaskInstance: etl_procesing.train_model manual__2023-11-18T04:33:23.188592+00:00 [queued]>
[2023-11-18T04:38:50.287+0000] {taskinstance.py:1361} INFO - Starting attempt 2 of 2
[2023-11-18T04:38:50.304+0000] {taskinstance.py:1382} INFO - Executing <Task(PythonOperator): train_model> on 2023-11-18 04:33:23.188592+00:00
[2023-11-18T04:38:50.320+0000] {standard_task_runner.py:57} INFO - Started process 14086 to run task
[2023-11-18T04:38:50.325+0000] {standard_task_runner.py:84} INFO - Running: ['***', 'tasks', 'run', 'etl_procesing', 'train_model', 'manual__2023-11-18T04:33:23.188592+00:00', '--job-id', '959', '--raw', '--subdir', 'DAGS_FOLDER/dag-lstm.py', '--cfg-path', '/tmp/tmpdmqvuvmf']
[2023-11-18T04:38:50.331+0000] {standard_task_runner.py:85} INFO - Job 959: Subtask train_model
[2023-11-18T04:38:50.408+0000] {task_command.py:416} INFO - Running <TaskInstance: etl_procesing.train_model manual__2023-11-18T04:33:23.188592+00:00 [running]> on host 4c85f18ab3d7
[2023-11-18T04:38:50.538+0000] {taskinstance.py:1662} INFO - Exporting env vars: AIRFLOW_CTX_DAG_OWNER='nguyenthung' AIRFLOW_CTX_DAG_ID='etl_procesing' AIRFLOW_CTX_TASK_ID='train_model' AIRFLOW_CTX_EXECUTION_DATE='2023-11-18T04:33:23.188592+00:00' AIRFLOW_CTX_TRY_NUMBER='2' AIRFLOW_CTX_DAG_RUN_ID='manual__2023-11-18T04:33:23.188592+00:00'
[2023-11-18T04:38:50.926+0000] {taskinstance.py:1937} ERROR - Task failed with exception
Traceback (most recent call last):
  File "/home/airflow/.local/lib/python3.8/site-packages/airflow/operators/python.py", line 192, in execute
    return_value = self.execute_callable()
  File "/home/airflow/.local/lib/python3.8/site-packages/airflow/operators/python.py", line 209, in execute_callable
    return self.python_callable(*self.op_args, **self.op_kwargs)
  File "/opt/airflow/dags/dag-lstm.py", line 171, in train_model
    dataset_test = dataset_train[(dataset_train['date'].dt.year == 2018) | (dataset_train['date'].dt.year == 2019)]
  File "/home/airflow/.local/lib/python3.8/site-packages/pandas/core/generic.py", line 5989, in __getattr__
    return object.__getattribute__(self, name)
  File "/home/airflow/.local/lib/python3.8/site-packages/pandas/core/accessor.py", line 224, in __get__
    accessor_obj = self._accessor(obj)
  File "/home/airflow/.local/lib/python3.8/site-packages/pandas/core/indexes/accessors.py", line 580, in __new__
    raise AttributeError("Can only use .dt accessor with datetimelike values")
AttributeError: Can only use .dt accessor with datetimelike values
[2023-11-18T04:38:50.943+0000] {taskinstance.py:1400} INFO - Marking task as FAILED. dag_id=etl_procesing, task_id=train_model, execution_date=20231118T043323, start_date=20231118T043850, end_date=20231118T043850
[2023-11-18T04:38:50.981+0000] {standard_task_runner.py:104} ERROR - Failed to execute job 959 for task train_model (Can only use .dt accessor with datetimelike values; 14086)
[2023-11-18T04:38:51.022+0000] {local_task_job_runner.py:228} INFO - Task exited with return code 1
[2023-11-18T04:38:51.044+0000] {taskinstance.py:2778} INFO - 0 downstream tasks scheduled from follow-on schedule check
