[2023-11-12T11:14:11.271+0000] {taskinstance.py:1159} INFO - Dependencies all met for dep_context=non-requeueable deps ti=<TaskInstance: nguyenthung.caculate_square_amount manual__2023-11-12T11:14:04.703127+00:00 [queued]>
[2023-11-12T11:14:11.285+0000] {taskinstance.py:1159} INFO - Dependencies all met for dep_context=requeueable deps ti=<TaskInstance: nguyenthung.caculate_square_amount manual__2023-11-12T11:14:04.703127+00:00 [queued]>
[2023-11-12T11:14:11.285+0000] {taskinstance.py:1361} INFO - Starting attempt 1 of 2
[2023-11-12T11:14:11.303+0000] {taskinstance.py:1382} INFO - Executing <Task(PythonOperator): caculate_square_amount> on 2023-11-12 11:14:04.703127+00:00
[2023-11-12T11:14:11.312+0000] {standard_task_runner.py:57} INFO - Started process 19143 to run task
[2023-11-12T11:14:11.322+0000] {standard_task_runner.py:84} INFO - Running: ['***', 'tasks', 'run', 'nguyenthung', 'caculate_square_amount', 'manual__2023-11-12T11:14:04.703127+00:00', '--job-id', '108', '--raw', '--subdir', 'DAGS_FOLDER/dag-elt-example.py', '--cfg-path', '/tmp/tmpunrc35rh']
[2023-11-12T11:14:11.329+0000] {standard_task_runner.py:85} INFO - Job 108: Subtask caculate_square_amount
[2023-11-12T11:14:11.467+0000] {task_command.py:416} INFO - Running <TaskInstance: nguyenthung.caculate_square_amount manual__2023-11-12T11:14:04.703127+00:00 [running]> on host 502cd78af35e
[2023-11-12T11:14:11.686+0000] {taskinstance.py:1662} INFO - Exporting env vars: AIRFLOW_CTX_DAG_OWNER='nguyenthung' AIRFLOW_CTX_DAG_ID='nguyenthung' AIRFLOW_CTX_TASK_ID='caculate_square_amount' AIRFLOW_CTX_EXECUTION_DATE='2023-11-12T11:14:04.703127+00:00' AIRFLOW_CTX_TRY_NUMBER='1' AIRFLOW_CTX_DAG_RUN_ID='manual__2023-11-12T11:14:04.703127+00:00'
[2023-11-12T11:14:12.759+0000] {taskinstance.py:1937} ERROR - Task failed with exception
Traceback (most recent call last):
  File "/home/airflow/.local/lib/python3.8/site-packages/airflow/operators/python.py", line 192, in execute
    return_value = self.execute_callable()
  File "/home/airflow/.local/lib/python3.8/site-packages/airflow/operators/python.py", line 209, in execute_callable
    return self.python_callable(*self.op_args, **self.op_kwargs)
  File "/opt/airflow/dags/dag-elt-example.py", line 67, in transform
    df.to_csv(out_csv_file_path, index=False)
  File "/home/airflow/.local/lib/python3.8/site-packages/pandas/core/generic.py", line 3772, in to_csv
    return DataFrameRenderer(formatter).to_csv(
  File "/home/airflow/.local/lib/python3.8/site-packages/pandas/io/formats/format.py", line 1186, in to_csv
    csv_formatter.save()
  File "/home/airflow/.local/lib/python3.8/site-packages/pandas/io/formats/csvs.py", line 240, in save
    with get_handle(
  File "/home/airflow/.local/lib/python3.8/site-packages/pandas/io/common.py", line 737, in get_handle
    check_parent_directory(str(handle))
  File "/home/airflow/.local/lib/python3.8/site-packages/pandas/io/common.py", line 600, in check_parent_directory
    raise OSError(rf"Cannot save file into a non-existent directory: '{parent}'")
OSError: Cannot save file into a non-existent directory: 'Airflow-Docker/data'
[2023-11-12T11:14:12.779+0000] {taskinstance.py:1400} INFO - Marking task as UP_FOR_RETRY. dag_id=nguyenthung, task_id=caculate_square_amount, execution_date=20231112T111404, start_date=20231112T111411, end_date=20231112T111412
[2023-11-12T11:14:12.796+0000] {standard_task_runner.py:104} ERROR - Failed to execute job 108 for task caculate_square_amount (Cannot save file into a non-existent directory: 'Airflow-Docker/data'; 19143)
[2023-11-12T11:14:12.837+0000] {local_task_job_runner.py:228} INFO - Task exited with return code 1
[2023-11-12T11:14:12.920+0000] {taskinstance.py:2778} INFO - 0 downstream tasks scheduled from follow-on schedule check
