[2023-11-15T02:35:04.277+0000] {taskinstance.py:1159} INFO - Dependencies all met for dep_context=non-requeueable deps ti=<TaskInstance: create_file_dag.create_file_task manual__2023-11-15T02:30:02.398801+00:00 [queued]>
[2023-11-15T02:35:04.290+0000] {taskinstance.py:1159} INFO - Dependencies all met for dep_context=requeueable deps ti=<TaskInstance: create_file_dag.create_file_task manual__2023-11-15T02:30:02.398801+00:00 [queued]>
[2023-11-15T02:35:04.291+0000] {taskinstance.py:1361} INFO - Starting attempt 2 of 2
[2023-11-15T02:35:04.305+0000] {taskinstance.py:1382} INFO - Executing <Task(PythonOperator): create_file_task> on 2023-11-15 02:30:02.398801+00:00
[2023-11-15T02:35:04.312+0000] {standard_task_runner.py:57} INFO - Started process 6194 to run task
[2023-11-15T02:35:04.316+0000] {standard_task_runner.py:84} INFO - Running: ['***', 'tasks', 'run', 'create_file_dag', 'create_file_task', 'manual__2023-11-15T02:30:02.398801+00:00', '--job-id', '274', '--raw', '--subdir', 'DAGS_FOLDER/createFile.py', '--cfg-path', '/tmp/tmpk57v847o']
[2023-11-15T02:35:04.319+0000] {standard_task_runner.py:85} INFO - Job 274: Subtask create_file_task
[2023-11-15T02:35:04.377+0000] {task_command.py:416} INFO - Running <TaskInstance: create_file_dag.create_file_task manual__2023-11-15T02:30:02.398801+00:00 [running]> on host 502cd78af35e
[2023-11-15T02:35:04.468+0000] {taskinstance.py:1662} INFO - Exporting env vars: AIRFLOW_CTX_DAG_OWNER='***' AIRFLOW_CTX_DAG_ID='create_file_dag' AIRFLOW_CTX_TASK_ID='create_file_task' AIRFLOW_CTX_EXECUTION_DATE='2023-11-15T02:30:02.398801+00:00' AIRFLOW_CTX_TRY_NUMBER='2' AIRFLOW_CTX_DAG_RUN_ID='manual__2023-11-15T02:30:02.398801+00:00'
[2023-11-15T02:35:04.469+0000] {taskinstance.py:1937} ERROR - Task failed with exception
Traceback (most recent call last):
  File "/home/airflow/.local/lib/python3.8/site-packages/airflow/operators/python.py", line 192, in execute
    return_value = self.execute_callable()
  File "/home/airflow/.local/lib/python3.8/site-packages/airflow/operators/python.py", line 209, in execute_callable
    return self.python_callable(*self.op_args, **self.op_kwargs)
  File "/opt/airflow/dags/createFile.py", line 13, in create_file
    os.makedirs(directory)
  File "/usr/local/lib/python3.8/os.py", line 213, in makedirs
    makedirs(head, exist_ok=exist_ok)
  File "/usr/local/lib/python3.8/os.py", line 213, in makedirs
    makedirs(head, exist_ok=exist_ok)
  File "/usr/local/lib/python3.8/os.py", line 213, in makedirs
    makedirs(head, exist_ok=exist_ok)
  File "/usr/local/lib/python3.8/os.py", line 223, in makedirs
    mkdir(name, mode)
PermissionError: [Errno 13] Permission denied: '/home/nguyenthung'
[2023-11-15T02:35:04.481+0000] {taskinstance.py:1400} INFO - Marking task as FAILED. dag_id=create_file_dag, task_id=create_file_task, execution_date=20231115T023002, start_date=20231115T023504, end_date=20231115T023504
[2023-11-15T02:35:04.494+0000] {standard_task_runner.py:104} ERROR - Failed to execute job 274 for task create_file_task ([Errno 13] Permission denied: '/home/nguyenthung'; 6194)
[2023-11-15T02:35:04.531+0000] {local_task_job_runner.py:228} INFO - Task exited with return code 1
[2023-11-15T02:35:04.556+0000] {taskinstance.py:2778} INFO - 0 downstream tasks scheduled from follow-on schedule check
