[2023-11-17T06:55:44.035+0000] {taskinstance.py:1159} INFO - Dependencies all met for dep_context=non-requeueable deps ti=<TaskInstance: etl_procesing.train_model manual__2023-11-17T06:55:24.874290+00:00 [queued]>
[2023-11-17T06:55:44.046+0000] {taskinstance.py:1159} INFO - Dependencies all met for dep_context=requeueable deps ti=<TaskInstance: etl_procesing.train_model manual__2023-11-17T06:55:24.874290+00:00 [queued]>
[2023-11-17T06:55:44.047+0000] {taskinstance.py:1361} INFO - Starting attempt 1 of 2
[2023-11-17T06:55:44.060+0000] {taskinstance.py:1382} INFO - Executing <Task(PythonOperator): train_model> on 2023-11-17 06:55:24.874290+00:00
[2023-11-17T06:55:44.071+0000] {standard_task_runner.py:57} INFO - Started process 47586 to run task
[2023-11-17T06:55:44.076+0000] {standard_task_runner.py:84} INFO - Running: ['***', 'tasks', 'run', 'etl_procesing', 'train_model', 'manual__2023-11-17T06:55:24.874290+00:00', '--job-id', '911', '--raw', '--subdir', 'DAGS_FOLDER/dag-lstm.py', '--cfg-path', '/tmp/tmpcfta4mtb']
[2023-11-17T06:55:44.080+0000] {standard_task_runner.py:85} INFO - Job 911: Subtask train_model
[2023-11-17T06:55:44.131+0000] {task_command.py:416} INFO - Running <TaskInstance: etl_procesing.train_model manual__2023-11-17T06:55:24.874290+00:00 [running]> on host 4c85f18ab3d7
[2023-11-17T06:55:44.222+0000] {taskinstance.py:1662} INFO - Exporting env vars: AIRFLOW_CTX_DAG_OWNER='nguyenthung' AIRFLOW_CTX_DAG_ID='etl_procesing' AIRFLOW_CTX_TASK_ID='train_model' AIRFLOW_CTX_EXECUTION_DATE='2023-11-17T06:55:24.874290+00:00' AIRFLOW_CTX_TRY_NUMBER='1' AIRFLOW_CTX_DAG_RUN_ID='manual__2023-11-17T06:55:24.874290+00:00'
[2023-11-17T06:55:44.225+0000] {taskinstance.py:1937} ERROR - Task failed with exception
Traceback (most recent call last):
  File "/home/airflow/.local/lib/python3.8/site-packages/airflow/operators/python.py", line 192, in execute
    return_value = self.execute_callable()
  File "/home/airflow/.local/lib/python3.8/site-packages/airflow/operators/python.py", line 209, in execute_callable
    return self.python_callable(*self.op_args, **self.op_kwargs)
  File "/opt/airflow/dags/dag-lstm.py", line 158, in train_model
    dataset_train = pd.read_csv('data/stock_data/stock_price.csv')
  File "/home/airflow/.local/lib/python3.8/site-packages/pandas/io/parsers/readers.py", line 912, in read_csv
    return _read(filepath_or_buffer, kwds)
  File "/home/airflow/.local/lib/python3.8/site-packages/pandas/io/parsers/readers.py", line 577, in _read
    parser = TextFileReader(filepath_or_buffer, **kwds)
  File "/home/airflow/.local/lib/python3.8/site-packages/pandas/io/parsers/readers.py", line 1407, in __init__
    self._engine = self._make_engine(f, self.engine)
  File "/home/airflow/.local/lib/python3.8/site-packages/pandas/io/parsers/readers.py", line 1661, in _make_engine
    self.handles = get_handle(
  File "/home/airflow/.local/lib/python3.8/site-packages/pandas/io/common.py", line 859, in get_handle
    handle = open(
FileNotFoundError: [Errno 2] No such file or directory: 'data/stock_data/stock_price.csv'
[2023-11-17T06:55:44.260+0000] {taskinstance.py:1400} INFO - Marking task as UP_FOR_RETRY. dag_id=etl_procesing, task_id=train_model, execution_date=20231117T065524, start_date=20231117T065544, end_date=20231117T065544
[2023-11-17T06:55:44.273+0000] {standard_task_runner.py:104} ERROR - Failed to execute job 911 for task train_model ([Errno 2] No such file or directory: 'data/stock_data/stock_price.csv'; 47586)
[2023-11-17T06:55:44.291+0000] {local_task_job_runner.py:228} INFO - Task exited with return code 1
[2023-11-17T06:55:44.310+0000] {taskinstance.py:2778} INFO - 0 downstream tasks scheduled from follow-on schedule check
