[2023-11-17T05:46:57.469+0000] {taskinstance.py:1159} INFO - Dependencies all met for dep_context=non-requeueable deps ti=<TaskInstance: etl_procesing.load_phase scheduled__2023-11-16T05:41:22.368907+00:00 [queued]>
[2023-11-17T05:46:57.479+0000] {taskinstance.py:1159} INFO - Dependencies all met for dep_context=requeueable deps ti=<TaskInstance: etl_procesing.load_phase scheduled__2023-11-16T05:41:22.368907+00:00 [queued]>
[2023-11-17T05:46:57.480+0000] {taskinstance.py:1361} INFO - Starting attempt 2 of 2
[2023-11-17T05:46:57.495+0000] {taskinstance.py:1382} INFO - Executing <Task(PythonOperator): load_phase> on 2023-11-16 05:41:22.368907+00:00
[2023-11-17T05:46:57.509+0000] {standard_task_runner.py:57} INFO - Started process 35250 to run task
[2023-11-17T05:46:57.513+0000] {standard_task_runner.py:84} INFO - Running: ['***', 'tasks', 'run', 'etl_procesing', 'load_phase', 'scheduled__2023-11-16T05:41:22.368907+00:00', '--job-id', '883', '--raw', '--subdir', 'DAGS_FOLDER/dag-lstm.py', '--cfg-path', '/tmp/tmpmem076lc']
[2023-11-17T05:46:57.517+0000] {standard_task_runner.py:85} INFO - Job 883: Subtask load_phase
[2023-11-17T05:46:57.571+0000] {task_command.py:416} INFO - Running <TaskInstance: etl_procesing.load_phase scheduled__2023-11-16T05:41:22.368907+00:00 [running]> on host 4c85f18ab3d7
[2023-11-17T05:46:57.658+0000] {taskinstance.py:1662} INFO - Exporting env vars: AIRFLOW_CTX_DAG_OWNER='nguyenthung' AIRFLOW_CTX_DAG_ID='etl_procesing' AIRFLOW_CTX_TASK_ID='load_phase' AIRFLOW_CTX_EXECUTION_DATE='2023-11-16T05:41:22.368907+00:00' AIRFLOW_CTX_TRY_NUMBER='2' AIRFLOW_CTX_DAG_RUN_ID='scheduled__2023-11-16T05:41:22.368907+00:00'
[2023-11-17T05:46:57.665+0000] {taskinstance.py:1937} ERROR - Task failed with exception
Traceback (most recent call last):
  File "/home/airflow/.local/lib/python3.8/site-packages/airflow/operators/python.py", line 192, in execute
    return_value = self.execute_callable()
  File "/home/airflow/.local/lib/python3.8/site-packages/airflow/operators/python.py", line 209, in execute_callable
    return self.python_callable(*self.op_args, **self.op_kwargs)
  File "/opt/airflow/dags/dag-lstm.py", line 134, in load
    for row in reader:
ValueError: I/O operation on closed file.
[2023-11-17T05:46:57.676+0000] {taskinstance.py:1400} INFO - Marking task as FAILED. dag_id=etl_procesing, task_id=load_phase, execution_date=20231116T054122, start_date=20231117T054657, end_date=20231117T054657
[2023-11-17T05:46:57.707+0000] {standard_task_runner.py:104} ERROR - Failed to execute job 883 for task load_phase (I/O operation on closed file.; 35250)
[2023-11-17T05:46:57.728+0000] {local_task_job_runner.py:228} INFO - Task exited with return code 1
[2023-11-17T05:46:57.748+0000] {taskinstance.py:2778} INFO - 0 downstream tasks scheduled from follow-on schedule check
