[2023-11-17T07:38:20.057+0000] {taskinstance.py:1159} INFO - Dependencies all met for dep_context=non-requeueable deps ti=<TaskInstance: etl_procesing.load_phase manual__2023-11-17T07:32:59.402951+00:00 [queued]>
[2023-11-17T07:38:20.069+0000] {taskinstance.py:1159} INFO - Dependencies all met for dep_context=requeueable deps ti=<TaskInstance: etl_procesing.load_phase manual__2023-11-17T07:32:59.402951+00:00 [queued]>
[2023-11-17T07:38:20.069+0000] {taskinstance.py:1361} INFO - Starting attempt 2 of 2
[2023-11-17T07:38:20.083+0000] {taskinstance.py:1382} INFO - Executing <Task(PythonOperator): load_phase> on 2023-11-17 07:32:59.402951+00:00
[2023-11-17T07:38:20.094+0000] {standard_task_runner.py:57} INFO - Started process 55156 to run task
[2023-11-17T07:38:20.099+0000] {standard_task_runner.py:84} INFO - Running: ['***', 'tasks', 'run', 'etl_procesing', 'load_phase', 'manual__2023-11-17T07:32:59.402951+00:00', '--job-id', '925', '--raw', '--subdir', 'DAGS_FOLDER/dag-lstm.py', '--cfg-path', '/tmp/tmpjnpfgmfy']
[2023-11-17T07:38:20.104+0000] {standard_task_runner.py:85} INFO - Job 925: Subtask load_phase
[2023-11-17T07:38:20.159+0000] {task_command.py:416} INFO - Running <TaskInstance: etl_procesing.load_phase manual__2023-11-17T07:32:59.402951+00:00 [running]> on host 4c85f18ab3d7
[2023-11-17T07:38:20.253+0000] {taskinstance.py:1662} INFO - Exporting env vars: AIRFLOW_CTX_DAG_OWNER='nguyenthung' AIRFLOW_CTX_DAG_ID='etl_procesing' AIRFLOW_CTX_TASK_ID='load_phase' AIRFLOW_CTX_EXECUTION_DATE='2023-11-17T07:32:59.402951+00:00' AIRFLOW_CTX_TRY_NUMBER='2' AIRFLOW_CTX_DAG_RUN_ID='manual__2023-11-17T07:32:59.402951+00:00'
[2023-11-17T07:38:20.260+0000] {logging_mixin.py:151} INFO - None
[2023-11-17T07:38:20.261+0000] {taskinstance.py:1937} ERROR - Task failed with exception
Traceback (most recent call last):
  File "/home/airflow/.local/lib/python3.8/site-packages/airflow/operators/python.py", line 192, in execute
    return_value = self.execute_callable()
  File "/home/airflow/.local/lib/python3.8/site-packages/airflow/operators/python.py", line 209, in execute_callable
    return self.python_callable(*self.op_args, **self.op_kwargs)
  File "/opt/airflow/dags/dag-lstm.py", line 152, in load
    if csv_date > latest_date:
TypeError: '>' not supported between instances of 'datetime.date' and 'NoneType'
[2023-11-17T07:38:20.271+0000] {taskinstance.py:1400} INFO - Marking task as FAILED. dag_id=etl_procesing, task_id=load_phase, execution_date=20231117T073259, start_date=20231117T073820, end_date=20231117T073820
[2023-11-17T07:38:20.282+0000] {standard_task_runner.py:104} ERROR - Failed to execute job 925 for task load_phase ('>' not supported between instances of 'datetime.date' and 'NoneType'; 55156)
[2023-11-17T07:38:20.314+0000] {local_task_job_runner.py:228} INFO - Task exited with return code 1
[2023-11-17T07:38:20.338+0000] {taskinstance.py:2778} INFO - 0 downstream tasks scheduled from follow-on schedule check
