[2023-11-16T12:53:43.881+0000] {taskinstance.py:1159} INFO - Dependencies all met for dep_context=non-requeueable deps ti=<TaskInstance: miai_dag.caculate_square_amount manual__2023-11-16T12:53:37.372388+00:00 [queued]>
[2023-11-16T12:53:43.898+0000] {taskinstance.py:1159} INFO - Dependencies all met for dep_context=requeueable deps ti=<TaskInstance: miai_dag.caculate_square_amount manual__2023-11-16T12:53:37.372388+00:00 [queued]>
[2023-11-16T12:53:43.898+0000] {taskinstance.py:1361} INFO - Starting attempt 1 of 2
[2023-11-16T12:53:43.914+0000] {taskinstance.py:1382} INFO - Executing <Task(PythonOperator): caculate_square_amount> on 2023-11-16 12:53:37.372388+00:00
[2023-11-16T12:53:43.928+0000] {standard_task_runner.py:57} INFO - Started process 19840 to run task
[2023-11-16T12:53:43.935+0000] {standard_task_runner.py:84} INFO - Running: ['***', 'tasks', 'run', 'miai_dag', 'caculate_square_amount', 'manual__2023-11-16T12:53:37.372388+00:00', '--job-id', '812', '--raw', '--subdir', 'DAGS_FOLDER/dag-lstm.py', '--cfg-path', '/tmp/tmp96um7e8z']
[2023-11-16T12:53:43.941+0000] {standard_task_runner.py:85} INFO - Job 812: Subtask caculate_square_amount
[2023-11-16T12:53:44.029+0000] {task_command.py:416} INFO - Running <TaskInstance: miai_dag.caculate_square_amount manual__2023-11-16T12:53:37.372388+00:00 [running]> on host 4c85f18ab3d7
[2023-11-16T12:53:44.259+0000] {taskinstance.py:1662} INFO - Exporting env vars: AIRFLOW_CTX_DAG_OWNER='nguyenthung' AIRFLOW_CTX_DAG_ID='miai_dag' AIRFLOW_CTX_TASK_ID='caculate_square_amount' AIRFLOW_CTX_EXECUTION_DATE='2023-11-16T12:53:37.372388+00:00' AIRFLOW_CTX_TRY_NUMBER='1' AIRFLOW_CTX_DAG_RUN_ID='manual__2023-11-16T12:53:37.372388+00:00'
[2023-11-16T12:53:44.263+0000] {taskinstance.py:1937} ERROR - Task failed with exception
Traceback (most recent call last):
  File "/home/airflow/.local/lib/python3.8/site-packages/airflow/operators/python.py", line 192, in execute
    return_value = self.execute_callable()
  File "/home/airflow/.local/lib/python3.8/site-packages/airflow/operators/python.py", line 209, in execute_callable
    return self.python_callable(*self.op_args, **self.op_kwargs)
  File "/opt/airflow/dags/dag-lstm.py", line 72, in transform
    df = pd.read_csv(in_csv_file_path)
  File "/home/airflow/.local/lib/python3.8/site-packages/pandas/io/parsers/readers.py", line 912, in read_csv
    return _read(filepath_or_buffer, kwds)
  File "/home/airflow/.local/lib/python3.8/site-packages/pandas/io/parsers/readers.py", line 577, in _read
    parser = TextFileReader(filepath_or_buffer, **kwds)
  File "/home/airflow/.local/lib/python3.8/site-packages/pandas/io/parsers/readers.py", line 1407, in __init__
    self._engine = self._make_engine(f, self.engine)
  File "/home/airflow/.local/lib/python3.8/site-packages/pandas/io/parsers/readers.py", line 1661, in _make_engine
    self.handles = get_handle(
  File "/home/airflow/.local/lib/python3.8/site-packages/pandas/io/common.py", line 859, in get_handle
    handle = open(
FileNotFoundError: [Errno 2] No such file or directory: 'data/stock_price.csv'
[2023-11-16T12:53:44.289+0000] {taskinstance.py:1400} INFO - Marking task as UP_FOR_RETRY. dag_id=miai_dag, task_id=caculate_square_amount, execution_date=20231116T125337, start_date=20231116T125343, end_date=20231116T125344
[2023-11-16T12:53:44.308+0000] {standard_task_runner.py:104} ERROR - Failed to execute job 812 for task caculate_square_amount ([Errno 2] No such file or directory: 'data/stock_price.csv'; 19840)
[2023-11-16T12:53:44.350+0000] {local_task_job_runner.py:228} INFO - Task exited with return code 1
[2023-11-16T12:53:44.388+0000] {taskinstance.py:2778} INFO - 0 downstream tasks scheduled from follow-on schedule check
