[2023-11-18T04:24:59.271+0000] {taskinstance.py:1159} INFO - Dependencies all met for dep_context=non-requeueable deps ti=<TaskInstance: etl_procesing.load_phase manual__2023-11-18T04:24:40.579889+00:00 [queued]>
[2023-11-18T04:24:59.281+0000] {taskinstance.py:1159} INFO - Dependencies all met for dep_context=requeueable deps ti=<TaskInstance: etl_procesing.load_phase manual__2023-11-18T04:24:40.579889+00:00 [queued]>
[2023-11-18T04:24:59.281+0000] {taskinstance.py:1361} INFO - Starting attempt 1 of 2
[2023-11-18T04:24:59.294+0000] {taskinstance.py:1382} INFO - Executing <Task(PythonOperator): load_phase> on 2023-11-18 04:24:40.579889+00:00
[2023-11-18T04:24:59.303+0000] {standard_task_runner.py:57} INFO - Started process 11567 to run task
[2023-11-18T04:24:59.308+0000] {standard_task_runner.py:84} INFO - Running: ['***', 'tasks', 'run', 'etl_procesing', 'load_phase', 'manual__2023-11-18T04:24:40.579889+00:00', '--job-id', '953', '--raw', '--subdir', 'DAGS_FOLDER/dag-lstm.py', '--cfg-path', '/tmp/tmph3wqmicj']
[2023-11-18T04:24:59.312+0000] {standard_task_runner.py:85} INFO - Job 953: Subtask load_phase
[2023-11-18T04:24:59.365+0000] {task_command.py:416} INFO - Running <TaskInstance: etl_procesing.load_phase manual__2023-11-18T04:24:40.579889+00:00 [running]> on host 4c85f18ab3d7
[2023-11-18T04:24:59.586+0000] {taskinstance.py:1662} INFO - Exporting env vars: AIRFLOW_CTX_DAG_OWNER='nguyenthung' AIRFLOW_CTX_DAG_ID='etl_procesing' AIRFLOW_CTX_TASK_ID='load_phase' AIRFLOW_CTX_EXECUTION_DATE='2023-11-18T04:24:40.579889+00:00' AIRFLOW_CTX_TRY_NUMBER='1' AIRFLOW_CTX_DAG_RUN_ID='manual__2023-11-18T04:24:40.579889+00:00'
[2023-11-18T04:24:59.588+0000] {taskinstance.py:1937} ERROR - Task failed with exception
Traceback (most recent call last):
  File "/home/airflow/.local/lib/python3.8/site-packages/airflow/operators/python.py", line 192, in execute
    return_value = self.execute_callable()
  File "/home/airflow/.local/lib/python3.8/site-packages/airflow/operators/python.py", line 209, in execute_callable
    return self.python_callable(*self.op_args, **self.op_kwargs)
  File "/opt/airflow/dags/dag-lstm.py", line 95, in load
    conn = connect(
  File "/home/airflow/.local/lib/python3.8/site-packages/psycopg2/__init__.py", line 122, in connect
    conn = _connect(dsn, connection_factory=connection_factory, **kwasync)
psycopg2.OperationalError: connection to server at "172.19.0.4", port 5432 failed: Connection refused
	Is the server running on that host and accepting TCP/IP connections?

[2023-11-18T04:24:59.629+0000] {taskinstance.py:1400} INFO - Marking task as UP_FOR_RETRY. dag_id=etl_procesing, task_id=load_phase, execution_date=20231118T042440, start_date=20231118T042459, end_date=20231118T042459
[2023-11-18T04:24:59.760+0000] {standard_task_runner.py:104} ERROR - Failed to execute job 953 for task load_phase (connection to server at "172.19.0.4", port 5432 failed: Connection refused
	Is the server running on that host and accepting TCP/IP connections?
; 11567)
[2023-11-18T04:24:59.791+0000] {local_task_job_runner.py:228} INFO - Task exited with return code 1
[2023-11-18T04:24:59.821+0000] {taskinstance.py:2778} INFO - 0 downstream tasks scheduled from follow-on schedule check
