[2023-11-12T11:12:00.091+0000] {taskinstance.py:1159} INFO - Dependencies all met for dep_context=non-requeueable deps ti=<TaskInstance: nguyenthung.load_from_mysql scheduled__2023-11-11T00:00:00+00:00 [queued]>
[2023-11-12T11:12:00.195+0000] {taskinstance.py:1159} INFO - Dependencies all met for dep_context=requeueable deps ti=<TaskInstance: nguyenthung.load_from_mysql scheduled__2023-11-11T00:00:00+00:00 [queued]>
[2023-11-12T11:12:00.195+0000] {taskinstance.py:1361} INFO - Starting attempt 3 of 4
[2023-11-12T11:12:00.314+0000] {taskinstance.py:1382} INFO - Executing <Task(PythonOperator): load_from_mysql> on 2023-11-11 00:00:00+00:00
[2023-11-12T11:12:00.326+0000] {standard_task_runner.py:57} INFO - Started process 18762 to run task
[2023-11-12T11:12:00.388+0000] {standard_task_runner.py:84} INFO - Running: ['***', 'tasks', 'run', 'nguyenthung', 'load_from_mysql', 'scheduled__2023-11-11T00:00:00+00:00', '--job-id', '103', '--raw', '--subdir', 'DAGS_FOLDER/dag-elt-example.py', '--cfg-path', '/tmp/tmpihay2pc8']
[2023-11-12T11:12:00.395+0000] {standard_task_runner.py:85} INFO - Job 103: Subtask load_from_mysql
[2023-11-12T11:12:00.699+0000] {task_command.py:416} INFO - Running <TaskInstance: nguyenthung.load_from_mysql scheduled__2023-11-11T00:00:00+00:00 [running]> on host 502cd78af35e
[2023-11-12T11:12:00.980+0000] {taskinstance.py:1662} INFO - Exporting env vars: AIRFLOW_CTX_DAG_OWNER='nguyenthung' AIRFLOW_CTX_DAG_ID='nguyenthung' AIRFLOW_CTX_TASK_ID='load_from_mysql' AIRFLOW_CTX_EXECUTION_DATE='2023-11-11T00:00:00+00:00' AIRFLOW_CTX_TRY_NUMBER='3' AIRFLOW_CTX_DAG_RUN_ID='scheduled__2023-11-11T00:00:00+00:00'
[2023-11-12T11:12:00.982+0000] {taskinstance.py:1937} ERROR - Task failed with exception
Traceback (most recent call last):
  File "/home/airflow/.local/lib/python3.8/site-packages/airflow/operators/python.py", line 192, in execute
    return_value = self.execute_callable()
  File "/home/airflow/.local/lib/python3.8/site-packages/airflow/operators/python.py", line 209, in execute_callable
    return self.python_callable(*self.op_args, **self.op_kwargs)
  File "/opt/airflow/dags/dag-elt-example.py", line 16, in extract
    conn = psycopg2.connect(
  File "/home/airflow/.local/lib/python3.8/site-packages/psycopg2/__init__.py", line 122, in connect
    conn = _connect(dsn, connection_factory=connection_factory, **kwasync)
psycopg2.OperationalError: connection to server at "localhost" (127.0.0.1), port 5432 failed: Connection refused
	Is the server running on that host and accepting TCP/IP connections?
connection to server at "localhost" (::1), port 5432 failed: Cannot assign requested address
	Is the server running on that host and accepting TCP/IP connections?

[2023-11-12T11:12:01.032+0000] {taskinstance.py:1400} INFO - Marking task as UP_FOR_RETRY. dag_id=nguyenthung, task_id=load_from_mysql, execution_date=20231111T000000, start_date=20231112T111200, end_date=20231112T111201
[2023-11-12T11:12:01.058+0000] {standard_task_runner.py:104} ERROR - Failed to execute job 103 for task load_from_mysql (connection to server at "localhost" (127.0.0.1), port 5432 failed: Connection refused
	Is the server running on that host and accepting TCP/IP connections?
connection to server at "localhost" (::1), port 5432 failed: Cannot assign requested address
	Is the server running on that host and accepting TCP/IP connections?
; 18762)
[2023-11-12T11:12:01.090+0000] {local_task_job_runner.py:228} INFO - Task exited with return code 1
[2023-11-12T11:12:01.148+0000] {taskinstance.py:2778} INFO - 0 downstream tasks scheduled from follow-on schedule check
