[2023-11-15T05:04:41.291+0000] {taskinstance.py:1159} INFO - Dependencies all met for dep_context=non-requeueable deps ti=<TaskInstance: create_file_dag.create_file_task manual__2023-11-15T05:04:40.254466+00:00 [queued]>
[2023-11-15T05:04:41.306+0000] {taskinstance.py:1159} INFO - Dependencies all met for dep_context=requeueable deps ti=<TaskInstance: create_file_dag.create_file_task manual__2023-11-15T05:04:40.254466+00:00 [queued]>
[2023-11-15T05:04:41.306+0000] {taskinstance.py:1361} INFO - Starting attempt 1 of 2
[2023-11-15T05:04:41.329+0000] {taskinstance.py:1382} INFO - Executing <Task(PythonOperator): create_file_task> on 2023-11-15 05:04:40.254466+00:00
[2023-11-15T05:04:41.337+0000] {standard_task_runner.py:57} INFO - Started process 30355 to run task
[2023-11-15T05:04:41.342+0000] {standard_task_runner.py:84} INFO - Running: ['***', 'tasks', 'run', 'create_file_dag', 'create_file_task', 'manual__2023-11-15T05:04:40.254466+00:00', '--job-id', '276', '--raw', '--subdir', 'DAGS_FOLDER/createFile.py', '--cfg-path', '/tmp/tmp_f11scaw']
[2023-11-15T05:04:41.346+0000] {standard_task_runner.py:85} INFO - Job 276: Subtask create_file_task
[2023-11-15T05:04:41.427+0000] {task_command.py:416} INFO - Running <TaskInstance: create_file_dag.create_file_task manual__2023-11-15T05:04:40.254466+00:00 [running]> on host 502cd78af35e
[2023-11-15T05:04:41.538+0000] {taskinstance.py:1662} INFO - Exporting env vars: AIRFLOW_CTX_DAG_OWNER='***' AIRFLOW_CTX_DAG_ID='create_file_dag' AIRFLOW_CTX_TASK_ID='create_file_task' AIRFLOW_CTX_EXECUTION_DATE='2023-11-15T05:04:40.254466+00:00' AIRFLOW_CTX_TRY_NUMBER='1' AIRFLOW_CTX_DAG_RUN_ID='manual__2023-11-15T05:04:40.254466+00:00'
[2023-11-15T05:04:41.659+0000] {taskinstance.py:1937} ERROR - Task failed with exception
Traceback (most recent call last):
  File "/home/airflow/.local/lib/python3.8/site-packages/airflow/operators/python.py", line 192, in execute
    return_value = self.execute_callable()
  File "/home/airflow/.local/lib/python3.8/site-packages/airflow/operators/python.py", line 209, in execute_callable
    return self.python_callable(*self.op_args, **self.op_kwargs)
  File "/opt/airflow/dags/createFile.py", line 13, in create_file
    os.makedirs(directory)
  File "/usr/local/lib/python3.8/os.py", line 223, in makedirs
    mkdir(name, mode)
PermissionError: [Errno 13] Permission denied: '/data'
[2023-11-15T05:04:41.681+0000] {taskinstance.py:1400} INFO - Marking task as UP_FOR_RETRY. dag_id=create_file_dag, task_id=create_file_task, execution_date=20231115T050440, start_date=20231115T050441, end_date=20231115T050441
[2023-11-15T05:04:41.695+0000] {standard_task_runner.py:104} ERROR - Failed to execute job 276 for task create_file_task ([Errno 13] Permission denied: '/data'; 30355)
[2023-11-15T05:04:41.724+0000] {local_task_job_runner.py:228} INFO - Task exited with return code 1
[2023-11-15T05:04:41.749+0000] {taskinstance.py:2778} INFO - 0 downstream tasks scheduled from follow-on schedule check
