[2023-11-12T11:24:46.942+0000] {taskinstance.py:1159} INFO - Dependencies all met for dep_context=non-requeueable deps ti=<TaskInstance: nguyenthung.load_from_mysql manual__2023-11-12T11:24:44.833080+00:00 [queued]>
[2023-11-12T11:24:46.957+0000] {taskinstance.py:1159} INFO - Dependencies all met for dep_context=requeueable deps ti=<TaskInstance: nguyenthung.load_from_mysql manual__2023-11-12T11:24:44.833080+00:00 [queued]>
[2023-11-12T11:24:46.958+0000] {taskinstance.py:1361} INFO - Starting attempt 1 of 2
[2023-11-12T11:24:46.977+0000] {taskinstance.py:1382} INFO - Executing <Task(PythonOperator): load_from_mysql> on 2023-11-12 11:24:44.833080+00:00
[2023-11-12T11:24:46.985+0000] {standard_task_runner.py:57} INFO - Started process 20716 to run task
[2023-11-12T11:24:46.990+0000] {standard_task_runner.py:84} INFO - Running: ['***', 'tasks', 'run', 'nguyenthung', 'load_from_mysql', 'manual__2023-11-12T11:24:44.833080+00:00', '--job-id', '129', '--raw', '--subdir', 'DAGS_FOLDER/dag-elt-example.py', '--cfg-path', '/tmp/tmpwh9mdir8']
[2023-11-12T11:24:46.994+0000] {standard_task_runner.py:85} INFO - Job 129: Subtask load_from_mysql
[2023-11-12T11:24:47.079+0000] {task_command.py:416} INFO - Running <TaskInstance: nguyenthung.load_from_mysql manual__2023-11-12T11:24:44.833080+00:00 [running]> on host 502cd78af35e
[2023-11-12T11:24:47.186+0000] {taskinstance.py:1662} INFO - Exporting env vars: AIRFLOW_CTX_DAG_OWNER='nguyenthung' AIRFLOW_CTX_DAG_ID='nguyenthung' AIRFLOW_CTX_TASK_ID='load_from_mysql' AIRFLOW_CTX_EXECUTION_DATE='2023-11-12T11:24:44.833080+00:00' AIRFLOW_CTX_TRY_NUMBER='1' AIRFLOW_CTX_DAG_RUN_ID='manual__2023-11-12T11:24:44.833080+00:00'
[2023-11-12T11:24:48.552+0000] {taskinstance.py:1937} ERROR - Task failed with exception
Traceback (most recent call last):
  File "/home/airflow/.local/lib/python3.8/site-packages/airflow/operators/python.py", line 192, in execute
    return_value = self.execute_callable()
  File "/home/airflow/.local/lib/python3.8/site-packages/airflow/operators/python.py", line 209, in execute_callable
    return self.python_callable(*self.op_args, **self.op_kwargs)
  File "/opt/airflow/dags/dag-elt-example.py", line 47, in extract
    os.makedirs(directory)
  File "/usr/local/lib/python3.8/os.py", line 213, in makedirs
    makedirs(head, exist_ok=exist_ok)
  File "/usr/local/lib/python3.8/os.py", line 213, in makedirs
    makedirs(head, exist_ok=exist_ok)
  File "/usr/local/lib/python3.8/os.py", line 213, in makedirs
    makedirs(head, exist_ok=exist_ok)
  File "/usr/local/lib/python3.8/os.py", line 223, in makedirs
    mkdir(name, mode)
PermissionError: [Errno 13] Permission denied: '/home/nguyenthung'
[2023-11-12T11:24:48.584+0000] {taskinstance.py:1400} INFO - Marking task as UP_FOR_RETRY. dag_id=nguyenthung, task_id=load_from_mysql, execution_date=20231112T112444, start_date=20231112T112446, end_date=20231112T112448
[2023-11-12T11:24:48.599+0000] {standard_task_runner.py:104} ERROR - Failed to execute job 129 for task load_from_mysql ([Errno 13] Permission denied: '/home/nguyenthung'; 20716)
[2023-11-12T11:24:48.658+0000] {local_task_job_runner.py:228} INFO - Task exited with return code 1
[2023-11-12T11:24:48.686+0000] {taskinstance.py:2778} INFO - 0 downstream tasks scheduled from follow-on schedule check
