[2023-11-12T11:10:38.640+0000] {taskinstance.py:1159} INFO - Dependencies all met for dep_context=non-requeueable deps ti=<TaskInstance: nguyenthung.load_from_mysql manual__2023-11-12T11:10:36.173258+00:00 [queued]>
[2023-11-12T11:10:38.653+0000] {taskinstance.py:1159} INFO - Dependencies all met for dep_context=requeueable deps ti=<TaskInstance: nguyenthung.load_from_mysql manual__2023-11-12T11:10:36.173258+00:00 [queued]>
[2023-11-12T11:10:38.653+0000] {taskinstance.py:1361} INFO - Starting attempt 1 of 2
[2023-11-12T11:10:38.671+0000] {taskinstance.py:1382} INFO - Executing <Task(PythonOperator): load_from_mysql> on 2023-11-12 11:10:36.173258+00:00
[2023-11-12T11:10:38.679+0000] {standard_task_runner.py:57} INFO - Started process 18588 to run task
[2023-11-12T11:10:38.685+0000] {standard_task_runner.py:84} INFO - Running: ['***', 'tasks', 'run', 'nguyenthung', 'load_from_mysql', 'manual__2023-11-12T11:10:36.173258+00:00', '--job-id', '102', '--raw', '--subdir', 'DAGS_FOLDER/dag-elt-example.py', '--cfg-path', '/tmp/tmpgmv03wn3']
[2023-11-12T11:10:38.690+0000] {standard_task_runner.py:85} INFO - Job 102: Subtask load_from_mysql
[2023-11-12T11:10:38.759+0000] {task_command.py:416} INFO - Running <TaskInstance: nguyenthung.load_from_mysql manual__2023-11-12T11:10:36.173258+00:00 [running]> on host 502cd78af35e
[2023-11-12T11:10:38.867+0000] {taskinstance.py:1662} INFO - Exporting env vars: AIRFLOW_CTX_DAG_OWNER='nguyenthung' AIRFLOW_CTX_DAG_ID='nguyenthung' AIRFLOW_CTX_TASK_ID='load_from_mysql' AIRFLOW_CTX_EXECUTION_DATE='2023-11-12T11:10:36.173258+00:00' AIRFLOW_CTX_TRY_NUMBER='1' AIRFLOW_CTX_DAG_RUN_ID='manual__2023-11-12T11:10:36.173258+00:00'
[2023-11-12T11:10:38.888+0000] {taskinstance.py:1937} ERROR - Task failed with exception
Traceback (most recent call last):
  File "/home/airflow/.local/lib/python3.8/site-packages/airflow/operators/python.py", line 192, in execute
    return_value = self.execute_callable()
  File "/home/airflow/.local/lib/python3.8/site-packages/airflow/operators/python.py", line 209, in execute_callable
    return self.python_callable(*self.op_args, **self.op_kwargs)
  File "/opt/airflow/dags/dag-elt-example.py", line 16, in extract
    conn = psycopg2.connect(
  File "/home/airflow/.local/lib/python3.8/site-packages/psycopg2/__init__.py", line 122, in connect
    conn = _connect(dsn, connection_factory=connection_factory, **kwasync)
psycopg2.OperationalError: connection to server at "172.19.0.1", port 5432 failed: FATAL:  database "***_db" does not exist

[2023-11-12T11:10:38.900+0000] {taskinstance.py:1400} INFO - Marking task as UP_FOR_RETRY. dag_id=nguyenthung, task_id=load_from_mysql, execution_date=20231112T111036, start_date=20231112T111038, end_date=20231112T111038
[2023-11-12T11:10:38.916+0000] {standard_task_runner.py:104} ERROR - Failed to execute job 102 for task load_from_mysql (connection to server at "172.19.0.1", port 5432 failed: FATAL:  database "***_db" does not exist
; 18588)
[2023-11-12T11:10:38.953+0000] {local_task_job_runner.py:228} INFO - Task exited with return code 1
[2023-11-12T11:10:38.993+0000] {taskinstance.py:2778} INFO - 0 downstream tasks scheduled from follow-on schedule check
